<sdf version='1.6'>
  <world name='default'>
    <scene>
      <ambient>0.5 0.5 0.5 1</ambient>
      <background>0.5 0.5 0.5 1</background>
      <shadows>0</shadows>
    </scene>
    <physics name='default_physics' default='0' type='ode'>
      <ode>
        <solver>
          <type>quick</type>
          <iters>200</iters>
          <sor>1.3</sor>
          <use_dynamic_moi_rescaling>0</use_dynamic_moi_rescaling>
        </solver>
        <constraints>
          <cfm>0</cfm>
          <erp>0.2</erp>
          <contact_max_correcting_vel>100</contact_max_correcting_vel>
          <contact_surface_layer>0.001</contact_surface_layer>
        </constraints>
      </ode>
      <real_time_update_rate>1000</real_time_update_rate>
      <max_step_size>0.002</max_step_size>
      <real_time_factor>1</real_time_factor>
    </physics>
    <model name='docking_base'>
      <link name='docking_pattern'>
        <pose frame=''>2 0 0 0 -0 0</pose>
        <collision name='docking_pattern_collision'>
          <geometry>
            <mesh>
              <uri>model://media/models/docking_pattern/meshes/models/docking_pattern.stl</uri>
              <scale>1 1 1</scale>
            </mesh>
          </geometry>
          <max_contacts>10</max_contacts>
          <surface>
            <contact>
              <ode/>
            </contact>
            <bounce/>
            <friction>
              <torsional>
                <ode/>
              </torsional>
              <ode/>
            </friction>
          </surface>
        </collision>
        <visual name='docking_pattern_visual'>
          <geometry>
            <mesh>
              <uri>model://media/models/docking_pattern/meshes/models/docking_pattern.stl</uri>
              <scale>1 1 1</scale>
            </mesh>
          </geometry>
          <cast_shadows>0</cast_shadows>
        </visual>
        <self_collide>0</self_collide>
        <enable_wind>0</enable_wind>
        <kinematic>0</kinematic>
      </link>
      <static>1</static>
    </model>
    <model name='7thmap'>
      <pose frame=''>9 -10 0 0 -0 0</pose>
      <static>1</static>
      <link name='body'>
        <collision name='collision'>
          <geometry>
            <mesh>
              <uri>model://media/models/7thmap_new/7thmap.dae</uri>
            </mesh>
          </geometry>
          <surface>
            <friction>
              <ode>
                <mu>1e+08</mu>
                <mu2>1e+08</mu2>
                <fdir1>0 0 0</fdir1>
                <slip1>0</slip1>
                <slip2>0</slip2>
              </ode>
              <torsional>
                <ode/>
              </torsional>
            </friction>
            <bounce>
              <restitution_coefficient>0</restitution_coefficient>
              <threshold>1e+06</threshold>
            </bounce>
            <contact>
              <ode>
                <soft_cfm>0</soft_cfm>
                <soft_erp>0.2</soft_erp>
                <kp>1e+10</kp>
                <kd>1</kd>
                <max_vel>100</max_vel>
                <min_depth>0.0001</min_depth>
              </ode>
            </contact>
          </surface>
          <max_contacts>10</max_contacts>
        </collision>
        <visual name='visual'>
          <geometry>
            <mesh>
              <uri>model://media/models/7thmap_new/7thmap.dae</uri>
            </mesh>
          </geometry>
          <material>
            <script>
              <name>__default__</name>
              <uri>__default__</uri>
            </script>
          </material>
          <cast_shadows>0</cast_shadows>
        </visual>
        <velocity_decay>
          <linear>0</linear>
          <angular>0</angular>
        </velocity_decay>
        <self_collide>0</self_collide>
        <kinematic>0</kinematic>
        <enable_wind>0</enable_wind>
      </link>
      <static>1</static>
    </model>
    <light name='my_light_01' type='directional'>
      <pose frame=''>0 0 30 0 -0 0</pose>
      <diffuse>0.9 0.9 0.9 1</diffuse>
      <specular>0.6 0.6 0.6 1</specular>
      <attenuation>
        <range>20</range>
      </attenuation>
      <direction>0 0 -1</direction>
      <cast_shadows>0</cast_shadows>
    </light>
    <light name='my_light_02' type='directional'>
      <pose frame=''>0 0 30 0 -0 0</pose>
      <diffuse>0.9 0.9 0.9 1</diffuse>
      <specular>0.6 0.6 0.6 1</specular>
      <attenuation>
        <range>20</range>
      </attenuation>
      <direction>-1 0 0</direction>
      <cast_shadows>0</cast_shadows>
    </light>
    <light name='my_light_03' type='directional'>
      <pose frame=''>0 0 30 0 -0 0</pose>
      <diffuse>0.9 0.9 0.9 1</diffuse>
      <specular>0.6 0.6 0.6 1</specular>
      <attenuation>
        <range>20</range>
      </attenuation>
      <direction>0 -1 0</direction>
      <cast_shadows>0</cast_shadows>
    </light>
    <light name='my_light_04' type='directional'>
      <pose frame=''>0 0 30 0 -0 0</pose>
      <diffuse>0.9 0.9 0.9 1</diffuse>
      <specular>0.6 0.6 0.6 1</specular>
      <attenuation>
        <range>20</range>
      </attenuation>
      <direction>0 0 1</direction>
      <cast_shadows>0</cast_shadows>
    </light>
    <light name='my_light_05' type='directional'>
      <pose frame=''>0 0 30 0 -0 0</pose>
      <diffuse>0.9 0.9 0.9 1</diffuse>
      <specular>0.6 0.6 0.6 1</specular>
      <attenuation>
        <range>20</range>
      </attenuation>
      <direction>1 0 0</direction>
      <cast_shadows>0</cast_shadows>
    </light>
    <light name='my_light_06' type='directional'>
      <pose frame=''>0 0 30 0 -0 0</pose>
      <diffuse>0.9 0.9 0.9 1</diffuse>
      <specular>0.6 0.6 0.6 1</specular>
      <attenuation>
        <range>20</range>
      </attenuation>
      <direction>0 1 0</direction>
      <cast_shadows>0</cast_shadows>
    </light>
    <gravity>0 0 -9.8</gravity>
    <magnetic_field>6e-06 2.3e-05 -4.2e-05</magnetic_field>
    <atmosphere type='adiabatic'/>
    <wind/>
    <spherical_coordinates>
      <surface_model>EARTH_WGS84</surface_model>
      <latitude_deg>0</latitude_deg>
      <longitude_deg>0</longitude_deg>
      <elevation>0</elevation>
      <heading_deg>0</heading_deg>
    </spherical_coordinates>
    <model name='vizzy'>
      <link name='base_footprint'>
        <pose frame=''>0 0 0 0 -0 0</pose>
        <inertial>
          <pose frame=''>0.003585 -0 0.234654 0 -0 0</pose>
          <mass>61.745</mass>
          <inertia>
            <ixx>3000.06</ixx>
            <ixy>-1.50469e-06</ixy>
            <ixz>5.35286e-05</ixz>
            <iyy>3000.17</iyy>
            <iyz>2.02103e-07</iyz>
            <izz>30.1126</izz>
          </inertia>
        </inertial>
        <collision name='base_footprint_fixed_joint_lump__base_link_collision'>
          <pose frame=''>0.005454 -0.001 0.29 0 -0 -3.14159</pose>
          <geometry>
            <box>
              <size>0.08 0.35 0.45</size>
            </box>
          </geometry>
          <surface>
            <contact>
              <ode>
                <kp>1e+06</kp>
                <kd>1</kd>
              </ode>
            </contact>
            <friction>
              <ode>
                <mu>1</mu>
                <mu2>1</mu2>
              </ode>
              <torsional>
                <ode/>
              </torsional>
            </friction>
            <bounce/>
          </surface>
          <max_contacts>10</max_contacts>
        </collision>
        <collision name='base_footprint_fixed_joint_lump__b_caster_wheel_link_collision_1'>
          <pose frame=''>-0.246406 -0 0.05 0 -0 -3.14159</pose>
          <geometry>
            <sphere>
              <radius>0.05</radius>
            </sphere>
          </geometry>
          <surface>
            <contact>
              <ode>
                <kp>1e+07</kp>
                <kd>100000</kd>
              </ode>
            </contact>
            <friction>
              <ode>
                <mu>0</mu>
                <mu2>0</mu2>
              </ode>
              <torsional>
                <ode/>
              </torsional>
            </friction>
            <bounce/>
          </surface>
          <max_contacts>10</max_contacts>
        </collision>
        <collision name='base_footprint_fixed_joint_lump__f_caster_wheel_link_collision_2'>
          <pose frame=''>0.253593 0 0.05 0 -0 -3.14159</pose>
          <geometry>
            <sphere>
              <radius>0.05</radius>
            </sphere>
          </geometry>
          <surface>
            <contact>
              <ode>
                <kp>1e+07</kp>
                <kd>100000</kd>
              </ode>
            </contact>
            <friction>
              <ode>
                <mu>0</mu>
                <mu2>0</mu2>
              </ode>
              <torsional>
                <ode/>
              </torsional>
            </friction>
            <bounce/>
          </surface>
          <max_contacts>10</max_contacts>
        </collision>
        <visual name='base_footprint_fixed_joint_lump__base_link_visual'>
          <pose frame=''>0.005454 -0.001 0.237 0 -0 -3.14159</pose>
          <geometry>
            <mesh>
              <scale>1 1 1</scale>
              <uri>/home/flash/catkin_ws/src/vizzy/vizzy_description/meshes/base/segway.dae</uri>
            </mesh>
          </geometry>
          <material>
            <script>
              <uri>__default__</uri>
              <name>__default__</name>
            </script>
          </material>
        </visual>
        <visual name='base_footprint_fixed_joint_lump__b_caster_wheel_link_visual_1'>
          <pose frame=''>-0.246406 -0 0.05 0 -0 -3.14159</pose>
          <geometry>
            <sphere>
              <radius>0.05</radius>
            </sphere>
          </geometry>
          <material>
            <script>
              <name>Gazebo/Grey</name>
              <uri>file://media/materials/scripts/gazebo.material</uri>
            </script>
          </material>
        </visual>
        <visual name='base_footprint_fixed_joint_lump__f_caster_wheel_link_visual_2'>
          <pose frame=''>0.253593 0 0.05 0 -0 -3.14159</pose>
          <geometry>
            <sphere>
              <radius>0.05</radius>
            </sphere>
          </geometry>
          <material>
            <script>
              <name>Gazebo/Grey</name>
              <uri>file://media/materials/scripts/gazebo.material</uri>
            </script>
          </material>
        </visual>
        <visual name='base_footprint_fixed_joint_lump__nav_hokuyo_link_visual_3'>
          <pose frame=''>0.278593 -0.001 0.24212 0 -0 0</pose>
          <geometry>
            <mesh>
              <scale>1 1 1</scale>
              <uri>/home/flash/catkin_ws/src/vizzy/vizzy_description/meshes/hokuyo_utm30lx/hokuyo_utm_30lx.dae</uri>
            </mesh>
          </geometry>
        </visual>
        <visual name='base_footprint_fixed_joint_lump__nav_hokuyo_rear_link_visual_4'>
          <pose frame=''>-0.276407 -0.001 0.24212 0 -0 -3.14159</pose>
          <geometry>
            <mesh>
              <scale>0.0254 0.0254 0.0254</scale>
              <uri>/home/flash/catkin_ws/src/vizzy/vizzy_description/meshes/hokuyo.dae</uri>
            </mesh>
          </geometry>
        </visual>
        <velocity_decay/>
        <velocity_decay/>
        <velocity_decay/>
        <velocity_decay/>
        <sensor name='nav_hokuyo_laser' type='ray'>
          <always_on>1</always_on>
          <update_rate>40</update_rate>
          <visualize>0</visualize>
          <ray>
            <scan>
              <horizontal>
                <samples>640</samples>
                <resolution>1</resolution>
                <min_angle>-1.309</min_angle>
                <max_angle>1.309</max_angle>
              </horizontal>
              <vertical>
                <samples>1</samples>
                <min_angle>0</min_angle>
                <max_angle>0</max_angle>
              </vertical>
            </scan>
            <range>
              <min>0.02</min>
              <max>30</max>
              <resolution>0.03</resolution>
            </range>
            <noise>
              <type>gaussian</type>
              <mean>0</mean>
              <stddev>0.01</stddev>
            </noise>
          </ray>
          <plugin name='gazebo_ros_nav_hokuyo_laser_controller' filename='libgazebo_ros_laser.so'>
            <gaussianNoise>0.0</gaussianNoise>
            <alwaysOn>1</alwaysOn>
            <updateRate>40</updateRate>
            <topicName>scan</topicName>
            <frameName>nav_hokuyo_laser_link</frameName>
            <robotNamespace>/</robotNamespace>
          </plugin>
          <pose frame=''>0.278593 -0.001 0.24212 0 -0 0</pose>
        </sensor>
        <gravity>1</gravity>
        <velocity_decay/>
        <sensor name='nav_hokuyo_rear_laser' type='ray'>
          <always_on>1</always_on>
          <update_rate>10</update_rate>
          <visualize>0</visualize>
          <ray>
            <scan>
              <horizontal>
                <samples>640</samples>
                <resolution>1</resolution>
                <min_angle>-1.309</min_angle>
                <max_angle>1.309</max_angle>
              </horizontal>
              <vertical>
                <samples>1</samples>
                <min_angle>0</min_angle>
                <max_angle>0</max_angle>
              </vertical>
            </scan>
            <range>
              <min>0.02</min>
              <max>4</max>
              <resolution>0.03</resolution>
            </range>
            <noise>
              <type>gaussian</type>
              <mean>0</mean>
              <stddev>0.01</stddev>
            </noise>
          </ray>
          <plugin name='gazebo_ros_nav_hokuyo_rear_laser_controller' filename='libgazebo_ros_laser.so'>
            <gaussianNoise>0.0</gaussianNoise>
            <alwaysOn>1</alwaysOn>
            <updateRate>10</updateRate>
            <topicName>scan_rear</topicName>
            <frameName>nav_hokuyo_rear_laser_link</frameName>
            <robotNamespace>/</robotNamespace>
          </plugin>
          <pose frame=''>-0.276407 -0.001 0.24212 0 -0 -3.14159</pose>
        </sensor>
        <self_collide>0</self_collide>
        <enable_wind>0</enable_wind>
        <kinematic>0</kinematic>
      </link>
      <link name='l_wheel_link'>
        <pose frame=''>0.003594 0.245 0.19814 1.57079 1.57079 3.14159</pose>
        <inertial>
          <pose frame=''>0 0 0 -3.14159 -0 0</pose>
          <mass>5</mass>
          <inertia>
            <ixx>0.0505743</ixx>
            <ixy>0</ixy>
            <ixz>0</ixz>
            <iyy>0.0505743</iyy>
            <iyz>0</iyz>
            <izz>0.0981486</izz>
          </inertia>
        </inertial>
        <collision name='l_wheel_link_collision'>
          <pose frame=''>0 0 0 -3.14159 -0 0</pose>
          <geometry>
            <cylinder>
              <length>0.001</length>
              <radius>0.19814</radius>
            </cylinder>
          </geometry>
          <surface>
            <contact>
              <ode>
                <kp>1e+07</kp>
                <kd>100000</kd>
              </ode>
            </contact>
            <friction>
              <ode>
                <mu>100000</mu>
                <mu2>100000</mu2>
              </ode>
              <torsional>
                <ode/>
              </torsional>
            </friction>
            <bounce/>
          </surface>
          <max_contacts>1</max_contacts>
        </collision>
        <visual name='l_wheel_link_visual'>
          <pose frame=''>0 0 0 -3.14159 -0 0</pose>
          <geometry>
            <mesh>
              <scale>1 1 1</scale>
              <uri>/home/flash/catkin_ws/src/vizzy/vizzy_description/meshes/base/wheel.dae</uri>
            </mesh>
          </geometry>
          <material>
            <script>
              <uri>__default__</uri>
              <name>__default__</name>
            </script>
          </material>
        </visual>
        <gravity>1</gravity>
        <velocity_decay/>
        <self_collide>0</self_collide>
        <enable_wind>0</enable_wind>
        <kinematic>0</kinematic>
      </link>
      <joint name='l_wheel_joint' type='revolute'>
        <child>l_wheel_link</child>
        <parent>base_footprint</parent>
        <axis>
          <xyz>0 1 -0</xyz>
          <limit>
            <lower>-1e+16</lower>
            <upper>1e+16</upper>
          </limit>
          <dynamics>
            <spring_reference>0</spring_reference>
            <spring_stiffness>0</spring_stiffness>
          </dynamics>
          <use_parent_model_frame>1</use_parent_model_frame>
        </axis>
      </joint>
      <link name='r_wheel_link'>
        <pose frame=''>0.003594 -0.245 0.19814 1.57079 1.57079 3.14159</pose>
        <inertial>
          <pose frame=''>0 0 0 0 -0 0</pose>
          <mass>5</mass>
          <inertia>
            <ixx>0.0505743</ixx>
            <ixy>0</ixy>
            <ixz>0</ixz>
            <iyy>0.0505743</iyy>
            <iyz>0</iyz>
            <izz>0.0981486</izz>
          </inertia>
        </inertial>
        <collision name='r_wheel_link_collision'>
          <pose frame=''>0 0 0 0 -0 0</pose>
          <geometry>
            <cylinder>
              <length>0.001</length>
              <radius>0.19814</radius>
            </cylinder>
          </geometry>
          <surface>
            <contact>
              <ode>
                <kp>1e+07</kp>
                <kd>100000</kd>
              </ode>
            </contact>
            <friction>
              <ode>
                <mu>100000</mu>
                <mu2>100000</mu2>
              </ode>
              <torsional>
                <ode/>
              </torsional>
            </friction>
            <bounce/>
          </surface>
          <max_contacts>1</max_contacts>
        </collision>
        <visual name='r_wheel_link_visual'>
          <pose frame=''>0 0 0 0 -0 0</pose>
          <geometry>
            <mesh>
              <scale>1 1 1</scale>
              <uri>/home/flash/catkin_ws/src/vizzy/vizzy_description/meshes/base/wheel.dae</uri>
            </mesh>
          </geometry>
          <material>
            <script>
              <uri>__default__</uri>
              <name>__default__</name>
            </script>
          </material>
        </visual>
        <gravity>1</gravity>
        <velocity_decay/>
        <self_collide>0</self_collide>
        <enable_wind>0</enable_wind>
        <kinematic>0</kinematic>
      </link>
      <joint name='r_wheel_joint' type='revolute'>
        <child>r_wheel_link</child>
        <parent>base_footprint</parent>
        <axis>
          <xyz>0 1 -0</xyz>
          <limit>
            <lower>-1e+16</lower>
            <upper>1e+16</upper>
          </limit>
          <dynamics>
            <spring_reference>0</spring_reference>
            <spring_stiffness>0</spring_stiffness>
          </dynamics>
          <use_parent_model_frame>1</use_parent_model_frame>
        </axis>
      </joint>
      <link name='waist_link'>
        <pose frame=''>0 -0 0.58067 1.5708 -0 -3.14159</pose>
        <inertial>
          <pose frame=''>0 0.113168 0 3.14159 -0 3.14159</pose>
          <mass>1.52901</mass>
          <inertia>
            <ixx>0.0162857</ixx>
            <ixy>-0.000217388</ixy>
            <ixz>-2.16469e-06</ixz>
            <iyy>0.0042523</iyy>
            <iyz>0.00026159</iyz>
            <izz>0.0139648</izz>
          </inertia>
        </inertial>
        <collision name='waist_link_collision'>
          <pose frame=''>0 0.15 0 3.14159 -0 3.14159</pose>
          <geometry>
            <box>
              <size>0.06 0.355 0.08</size>
            </box>
          </geometry>
          <surface>
            <contact>
              <ode/>
            </contact>
            <friction>
              <ode>
                <mu>0.2</mu>
                <mu2>0.2</mu2>
              </ode>
              <torsional>
                <ode/>
              </torsional>
            </friction>
            <bounce/>
          </surface>
          <max_contacts>10</max_contacts>
        </collision>
        <visual name='waist_link_visual'>
          <pose frame=''>0 0 -0.067322 3.14159 -0 3.14159</pose>
          <geometry>
            <mesh>
              <scale>1 1 1</scale>
              <uri>/home/flash/catkin_ws/src/vizzy/vizzy_description/meshes/torso/waist_link.dae</uri>
            </mesh>
          </geometry>
          <material>
            <script>
              <uri>__default__</uri>
              <name>__default__</name>
            </script>
          </material>
        </visual>
        <gravity>1</gravity>
        <velocity_decay/>
        <self_collide>0</self_collide>
        <enable_wind>0</enable_wind>
        <kinematic>0</kinematic>
      </link>
      <joint name='waist_joint' type='revolute'>
        <child>waist_link</child>
        <parent>base_footprint</parent>
        <axis>
          <xyz>-0 1 -0</xyz>
          <limit>
            <lower>-0.349066</lower>
            <upper>0.349066</upper>
            <effort>525</effort>
            <velocity>0.593412</velocity>
          </limit>
          <dynamics>
            <spring_reference>0</spring_reference>
            <spring_stiffness>0</spring_stiffness>
          </dynamics>
          <use_parent_model_frame>1</use_parent_model_frame>
        </axis>
        <physics>
          <provide_feedback>1</provide_feedback>
          <ode>
            <provide_feedback>1</provide_feedback>
            <fudge_factor>1</fudge_factor>
            <limit>
              <cfm>1e+06</cfm>
              <erp>0.2</erp>
            </limit>
          </ode>
        </physics>
      </joint>
      <link name='l_shoulder_scapula_link'>
        <pose frame=''>-0 0.0805 0.58067 -3.14159 0.0175 -3.14159</pose>
        <inertial>
          <pose frame=''>0 0 -0.16 0 -0 0</pose>
          <mass>0.328838</mass>
          <inertia>
            <ixx>0.00123108</ixx>
            <ixy>-7.89159e-11</ixy>
            <ixz>6.34905e-10</ixz>
            <iyy>0.000919899</iyy>
            <iyz>7.50425e-05</iyz>
            <izz>0.000480034</izz>
          </inertia>
        </inertial>
        <collision name='l_shoulder_scapula_link_collision'>
          <pose frame=''>0 0 -0.1 0 -0 0</pose>
          <geometry>
            <cylinder>
              <length>0.11</length>
              <radius>0.027</radius>
            </cylinder>
          </geometry>
          <max_contacts>10</max_contacts>
          <surface>
            <contact>
              <ode/>
            </contact>
            <bounce/>
            <friction>
              <torsional>
                <ode/>
              </torsional>
              <ode/>
            </friction>
          </surface>
        </collision>
        <visual name='l_shoulder_scapula_link_visual'>
          <pose frame=''>0 0 -0.16 0 -0 0</pose>
          <geometry>
            <mesh>
              <scale>1 1 1</scale>
              <uri>/home/flash/catkin_ws/src/vizzy/vizzy_description/meshes/arm/l_shoulder_scapula.dae</uri>
            </mesh>
          </geometry>
        </visual>
        <self_collide>0</self_collide>
        <enable_wind>0</enable_wind>
        <kinematic>0</kinematic>
      </link>
      <joint name='l_shoulder_scapula_joint' type='revolute'>
        <child>l_shoulder_scapula_link</child>
        <parent>waist_link</parent>
        <axis>
          <xyz>0.017499 -0 -0.999847</xyz>
          <limit>
            <lower>-0.314159</lower>
            <upper>0.314159</upper>
            <effort>10</effort>
            <velocity>3</velocity>
          </limit>
          <dynamics>
            <damping>0</damping>
            <friction>0.1</friction>
            <spring_reference>0</spring_reference>
            <spring_stiffness>0</spring_stiffness>
          </dynamics>
          <use_parent_model_frame>1</use_parent_model_frame>
        </axis>
      </joint>
      <link name='l_shoulder_flection_link'>
        <pose frame=''>-0.00371 0.0805 0.792638 -1.5708 0.0175 -3.14159</pose>
        <inertial>
          <pose frame=''>0 0 -0.048 0 -0 2.08689</pose>
          <mass>0.329708</mass>
          <inertia>
            <ixx>0.00116793</ixx>
            <ixy>-0.00013489</ixy>
            <ixz>3.78931e-05</ixz>
            <iyy>0.00101232</iyy>
            <iyz>-6.56608e-05</iyz>
            <izz>0.000480379</izz>
          </inertia>
        </inertial>
        <collision name='l_shoulder_flection_link_collision'>
          <pose frame=''>0 0 -0.02 0 -0 2.08689</pose>
          <geometry>
            <cylinder>
              <length>0.1</length>
              <radius>0.025</radius>
            </cylinder>
          </geometry>
          <max_contacts>10</max_contacts>
          <surface>
            <contact>
              <ode/>
            </contact>
            <bounce/>
            <friction>
              <torsional>
                <ode/>
              </torsional>
              <ode/>
            </friction>
          </surface>
        </collision>
        <visual name='l_shoulder_flection_link_visual'>
          <pose frame=''>0 0 -0.048 0 -0 2.08689</pose>
          <geometry>
            <mesh>
              <scale>1 1 1</scale>
              <uri>/home/flash/catkin_ws/src/vizzy/vizzy_description/meshes/arm/l_shoulder_flection.dae</uri>
            </mesh>
          </geometry>
        </visual>
        <self_collide>0</self_collide>
        <enable_wind>0</enable_wind>
        <kinematic>0</kinematic>
      </link>
      <joint name='l_shoulder_flection_joint' type='revolute'>
        <child>l_shoulder_flection_link</child>
        <parent>l_shoulder_scapula_link</parent>
        <axis>
          <xyz>0 -1 0</xyz>
          <limit>
            <lower>-1.309</lower>
            <upper>2.35619</upper>
            <effort>10</effort>
            <velocity>3</velocity>
          </limit>
          <dynamics>
            <damping>0</damping>
            <friction>0.1</friction>
            <spring_reference>0</spring_reference>
            <spring_stiffness>0</spring_stiffness>
          </dynamics>
          <use_parent_model_frame>1</use_parent_model_frame>
        </axis>
      </joint>
      <link name='l_shoulder_abduction_link'>
        <pose frame=''>-0.00371 0.18306 0.792638 -0 -1.5533 3.14159</pose>
        <inertial>
          <pose frame=''>-0.034 -0.009 -0.001 0 -0 1.91989</pose>
          <mass>0.337952</mass>
          <inertia>
            <ixx>0.000722844</ixx>
            <ixy>-4.62402e-05</ixy>
            <ixz>-1.45397e-06</ixz>
            <iyy>0.000316567</iyy>
            <iyz>1.40156e-05</iyz>
            <izz>0.00057776</izz>
          </inertia>
        </inertial>
        <collision name='l_shoulder_abduction_link_collision'>
          <pose frame=''>0 0 0 0 -0 1.91989</pose>
          <geometry>
            <cylinder>
              <length>0.11</length>
              <radius>0.028</radius>
            </cylinder>
          </geometry>
          <max_contacts>10</max_contacts>
          <surface>
            <contact>
              <ode/>
            </contact>
            <bounce/>
            <friction>
              <torsional>
                <ode/>
              </torsional>
              <ode/>
            </friction>
          </surface>
        </collision>
        <visual name='l_shoulder_abduction_link_visual'>
          <pose frame=''>-0.034 -0.009 -0.001 0 -0 1.91989</pose>
          <geometry>
            <mesh>
              <scale>1 1 1</scale>
              <uri>/home/flash/catkin_ws/src/vizzy/vizzy_description/meshes/arm/l_shoulder_abduction.dae</uri>
            </mesh>
          </geometry>
        </visual>
        <self_collide>0</self_collide>
        <enable_wind>0</enable_wind>
        <kinematic>0</kinematic>
      </link>
      <joint name='l_shoulder_abduction_joint' type='revolute'>
        <child>l_shoulder_abduction_link</child>
        <parent>l_shoulder_flection_link</parent>
        <axis>
          <xyz>0.999847 0 0.017499</xyz>
          <limit>
            <lower>0</lower>
            <upper>1.309</upper>
            <effort>10</effort>
            <velocity>3</velocity>
          </limit>
          <dynamics>
            <damping>0</damping>
            <friction>0.1</friction>
            <spring_reference>0</spring_reference>
            <spring_stiffness>0</spring_stiffness>
          </dynamics>
          <use_parent_model_frame>1</use_parent_model_frame>
        </axis>
      </joint>
      <link name='l_shoulder_rotation_link'>
        <pose frame=''>-0.00371 0.18306 0.792638 0.018623 0.34901 -1.56443</pose>
        <inertial>
          <pose frame=''>0.003 -0.006 -0.127 0 -0 1.5708</pose>
          <mass>0.302328</mass>
          <inertia>
            <ixx>0.000615246</ixx>
            <ixy>4.12484e-06</ixy>
            <ixz>6.13277e-05</ixz>
            <iyy>0.000574849</iyy>
            <iyz>-2.49115e-05</iyz>
            <izz>0.000240227</izz>
          </inertia>
        </inertial>
        <collision name='l_shoulder_rotation_link_collision'>
          <pose frame=''>0 0 -0.08 0 -0 1.5708</pose>
          <geometry>
            <cylinder>
              <length>0.09</length>
              <radius>0.028</radius>
            </cylinder>
          </geometry>
          <max_contacts>10</max_contacts>
          <surface>
            <contact>
              <ode/>
            </contact>
            <bounce/>
            <friction>
              <torsional>
                <ode/>
              </torsional>
              <ode/>
            </friction>
          </surface>
        </collision>
        <visual name='l_shoulder_rotation_link_visual'>
          <pose frame=''>0.003 -0.006 -0.127 0 -0 1.5708</pose>
          <geometry>
            <mesh>
              <scale>1 1 1</scale>
              <uri>/home/flash/catkin_ws/src/vizzy/vizzy_description/meshes/arm/l_shoulder_rotation.dae</uri>
            </mesh>
          </geometry>
        </visual>
        <self_collide>0</self_collide>
        <enable_wind>0</enable_wind>
        <kinematic>0</kinematic>
      </link>
      <joint name='l_shoulder_rotation_joint' type='revolute'>
        <child>l_shoulder_rotation_link</child>
        <parent>l_shoulder_abduction_link</parent>
        <axis>
          <xyz>-0.016444 -0.34202 0.939549</xyz>
          <limit>
            <lower>-1.48353</lower>
            <upper>1.48353</upper>
            <effort>10</effort>
            <velocity>3</velocity>
          </limit>
          <dynamics>
            <damping>0</damping>
            <friction>0.1</friction>
            <spring_reference>0</spring_reference>
            <spring_stiffness>0</spring_stiffness>
          </dynamics>
          <use_parent_model_frame>1</use_parent_model_frame>
        </axis>
      </joint>
      <link name='l_elbow_flection_link'>
        <pose frame=''>-0.00103 0.238796 0.639529 1.91986 -0.0175 0</pose>
        <inertial>
          <pose frame=''>0.002 -0.035 0 3.14159 0 0.0873</pose>
          <mass>0.302328</mass>
          <inertia>
            <ixx>0.000615246</ixx>
            <ixy>4.12484e-06</ixy>
            <ixz>6.13277e-05</ixz>
            <iyy>0.000574849</iyy>
            <iyz>-2.49115e-05</iyz>
            <izz>0.000240227</izz>
          </inertia>
        </inertial>
        <collision name='l_elbow_flection_link_collision'>
          <pose frame=''>0 0 0 0 -0 0</pose>
          <geometry>
            <cylinder>
              <length>0.07</length>
              <radius>0.025</radius>
            </cylinder>
          </geometry>
          <max_contacts>10</max_contacts>
          <surface>
            <contact>
              <ode/>
            </contact>
            <bounce/>
            <friction>
              <torsional>
                <ode/>
              </torsional>
              <ode/>
            </friction>
          </surface>
        </collision>
        <visual name='l_elbow_flection_link_visual'>
          <pose frame=''>0.002 -0.035 0 3.14159 0 0.0873</pose>
          <geometry>
            <mesh>
              <scale>1 1 1</scale>
              <uri>/home/flash/catkin_ws/src/vizzy/vizzy_description/meshes/arm/l_elbow_flection.dae</uri>
            </mesh>
          </geometry>
        </visual>
        <self_collide>0</self_collide>
        <enable_wind>0</enable_wind>
        <kinematic>0</kinematic>
      </link>
      <joint name='l_elbow_flection_joint' type='revolute'>
        <child>l_elbow_flection_link</child>
        <parent>l_shoulder_rotation_link</parent>
        <axis>
          <xyz>0.005985 -0.939693 -0.341968</xyz>
          <limit>
            <lower>0</lower>
            <upper>1.91986</upper>
            <effort>10</effort>
            <velocity>3</velocity>
          </limit>
          <dynamics>
            <damping>0</damping>
            <friction>0.1</friction>
            <spring_reference>0</spring_reference>
            <spring_stiffness>0</spring_stiffness>
          </dynamics>
          <use_parent_model_frame>1</use_parent_model_frame>
        </axis>
      </joint>
      <link name='l_forearm_pronation_link'>
        <pose frame=''>-0.00103 0.238796 0.639529 -2.79077 -0.099515 -0.029973</pose>
        <inertial>
          <pose frame=''>0 0.007 0.11 -3.14159 -0 1.5708</pose>
          <mass>0.192525</mass>
          <inertia>
            <ixx>0.000215803</ixx>
            <ixy>6.01824e-08</ixy>
            <ixz>-9.78526e-06</ixz>
            <iyy>0.000229048</iyy>
            <iyz>-3.21836e-07</iyz>
            <izz>0.000102659</izz>
          </inertia>
        </inertial>
        <collision name='l_forearm_pronation_link_collision'>
          <pose frame=''>0 0 0.09 0 -0 0</pose>
          <geometry>
            <cylinder>
              <length>0.1</length>
              <radius>0.025</radius>
            </cylinder>
          </geometry>
          <max_contacts>10</max_contacts>
          <surface>
            <contact>
              <ode/>
            </contact>
            <bounce/>
            <friction>
              <torsional>
                <ode/>
              </torsional>
              <ode/>
            </friction>
          </surface>
        </collision>
        <visual name='l_forearm_pronation_link_visual'>
          <pose frame=''>0 0.007 0.11 -3.14159 -0 1.5708</pose>
          <geometry>
            <mesh>
              <scale>1 1 1</scale>
              <uri>/home/flash/catkin_ws/src/vizzy/vizzy_description/meshes/arm/l_forearm_pronation.dae</uri>
            </mesh>
          </geometry>
        </visual>
        <self_collide>0</self_collide>
        <enable_wind>0</enable_wind>
        <kinematic>0</kinematic>
      </link>
      <joint name='l_forearm_pronation_joint' type='revolute'>
        <child>l_forearm_pronation_link</child>
        <parent>l_elbow_flection_link</parent>
        <axis>
          <xyz>0.103557 0.340718 -0.934445</xyz>
          <limit>
            <lower>-1.48353</lower>
            <upper>1.48353</upper>
            <effort>10</effort>
            <velocity>3</velocity>
          </limit>
          <dynamics>
            <damping>0</damping>
            <friction>0.1</friction>
            <spring_reference>0</spring_reference>
            <spring_stiffness>0</spring_stiffness>
          </dynamics>
          <use_parent_model_frame>1</use_parent_model_frame>
        </axis>
      </joint>
      <link name='l_wrist_abduction_link'>
        <pose frame=''>0.018568 0.303276 0.462685 -1.21998 -0.099515 -0.029973</pose>
        <inertial>
          <pose frame=''>-0.0047 -0.028 -0.003 0 -0 0</pose>
          <mass>0.151303</mass>
          <inertia>
            <ixx>0.000116374</ixx>
            <ixy>1.3101e-05</ixy>
            <ixz>6.69704e-05</ixz>
            <iyy>0.000200316</iyy>
            <iyz>1.00269e-05</iyz>
            <izz>0.000162164</izz>
          </inertia>
        </inertial>
        <collision name='l_wrist_abduction_link_collision'>
          <pose frame=''>0 0 0 3.14159 1.57079 3e-06</pose>
          <geometry>
            <cylinder>
              <length>0.06</length>
              <radius>0.025</radius>
            </cylinder>
          </geometry>
          <max_contacts>10</max_contacts>
          <surface>
            <contact>
              <ode/>
            </contact>
            <bounce/>
            <friction>
              <torsional>
                <ode/>
              </torsional>
              <ode/>
            </friction>
          </surface>
        </collision>
        <visual name='l_wrist_abduction_link_visual'>
          <pose frame=''>-0.0047 -0.028 -0.003 0 -0 0</pose>
          <geometry>
            <mesh>
              <scale>1 1 1</scale>
              <uri>/home/flash/catkin_ws/src/vizzy/vizzy_description/meshes/arm/l_wrist_abduction.dae</uri>
            </mesh>
          </geometry>
        </visual>
        <self_collide>0</self_collide>
        <enable_wind>0</enable_wind>
        <kinematic>0</kinematic>
      </link>
      <joint name='l_wrist_abduction_joint' type='revolute'>
        <child>l_wrist_abduction_link</child>
        <parent>l_forearm_pronation_link</parent>
        <axis>
          <xyz>-0.005985 0.939693 0.341968</xyz>
          <limit>
            <lower>-0.610865</lower>
            <upper>0.610865</upper>
            <effort>10</effort>
            <velocity>3</velocity>
          </limit>
          <dynamics>
            <damping>0</damping>
            <friction>0.1</friction>
            <spring_reference>0</spring_reference>
            <spring_stiffness>0</spring_stiffness>
          </dynamics>
          <use_parent_model_frame>1</use_parent_model_frame>
        </axis>
      </joint>
      <link name='l_wrist_flection_link'>
        <pose frame=''>0.018568 0.303276 0.462685 1.85354 -1.2067 -1.86586</pose>
        <inertial>
          <pose frame=''>-0.106 -0.0077 -0.017 0 -0 1.5708</pose>
          <mass>0.263178</mass>
          <inertia>
            <ixx>0.00141537</ixx>
            <ixy>-5.47007e-06</ixy>
            <ixz>4.93142e-05</ixz>
            <iyy>0.000423838</iyy>
            <iyz>0.000132116</iyz>
            <izz>0.00103376</izz>
          </inertia>
        </inertial>
        <collision name='l_wrist_flection_link_collision'>
          <pose frame=''>-0.106 -0.0077 0 0 -0 0</pose>
          <geometry>
            <box>
              <size>0.11 0.015 0.1</size>
            </box>
          </geometry>
          <max_contacts>10</max_contacts>
          <surface>
            <contact>
              <ode/>
            </contact>
            <bounce/>
            <friction>
              <torsional>
                <ode/>
              </torsional>
              <ode/>
            </friction>
          </surface>
        </collision>
        <visual name='l_wrist_flection_link_visual'>
          <pose frame=''>-0.106 -0.0077 -0.017 0 -0 1.5708</pose>
          <geometry>
            <mesh>
              <scale>1 1 1</scale>
              <uri>/home/flash/catkin_ws/src/vizzy/vizzy_description/meshes/arm/l_wrist_flection_simple.dae</uri>
            </mesh>
          </geometry>
        </visual>
        <self_collide>0</self_collide>
        <enable_wind>0</enable_wind>
        <kinematic>0</kinematic>
      </link>
      <joint name='l_wrist_flection_joint' type='revolute'>
        <child>l_wrist_flection_link</child>
        <parent>l_wrist_abduction_link</parent>
        <axis>
          <xyz>-0.994606 0.02982 -0.099351</xyz>
          <limit>
            <lower>-0.610865</lower>
            <upper>0.610865</upper>
            <effort>10</effort>
            <velocity>3</velocity>
          </limit>
          <dynamics>
            <damping>0</damping>
            <friction>0.1</friction>
            <spring_reference>0</spring_reference>
            <spring_stiffness>0</spring_stiffness>
          </dynamics>
          <use_parent_model_frame>1</use_parent_model_frame>
        </axis>
      </joint>
      <link name='neck_pan_link'>
        <pose frame=''>0 -0 0.58067 -3.14159 -0 -3.14159</pose>
        <inertial>
          <pose frame=''>0 0 -0.327 0 0 -1.5708</pose>
          <mass>0.223144</mass>
          <inertia>
            <ixx>0.000359045</ixx>
            <ixy>3.18554e-08</ixy>
            <ixz>-1.3374e-05</ixz>
            <iyy>0.000368715</iyy>
            <iyz>-4.52682e-07</iyz>
            <izz>8.59049e-05</izz>
          </inertia>
        </inertial>
        <collision name='neck_pan_link_collision'>
          <pose frame=''>0 0 -0.37 -1.5708 0 0</pose>
          <geometry>
            <cylinder>
              <length>0.07</length>
              <radius>0.02</radius>
            </cylinder>
          </geometry>
          <max_contacts>10</max_contacts>
          <surface>
            <contact>
              <ode/>
            </contact>
            <bounce/>
            <friction>
              <torsional>
                <ode/>
              </torsional>
              <ode/>
            </friction>
          </surface>
        </collision>
        <visual name='neck_pan_link_visual'>
          <pose frame=''>0 0 -0.327 0 0 -1.5708</pose>
          <geometry>
            <mesh>
              <scale>1 1 1</scale>
              <uri>/home/flash/catkin_ws/src/vizzy/vizzy_description/meshes/head/neck_pan.dae</uri>
            </mesh>
          </geometry>
        </visual>
        <self_collide>0</self_collide>
        <enable_wind>0</enable_wind>
        <kinematic>0</kinematic>
      </link>
      <joint name='neck_pan_joint' type='revolute'>
        <child>neck_pan_link</child>
        <parent>waist_link</parent>
        <axis>
          <xyz>0 -0 -1</xyz>
          <limit>
            <lower>-2.02502</lower>
            <upper>2.02502</upper>
            <effort>100</effort>
            <velocity>5</velocity>
          </limit>
          <dynamics>
            <damping>5</damping>
            <friction>10</friction>
            <spring_reference>0</spring_reference>
            <spring_stiffness>0</spring_stiffness>
          </dynamics>
          <use_parent_model_frame>1</use_parent_model_frame>
        </axis>
      </joint>
      <link name='neck_tilt_link'>
        <pose frame=''>-0 0 0.95067 -1.5708 -0 -3.14159</pose>
        <inertial>
          <pose frame=''>-0.026731 -0.026889 0 0 -0 3.14159</pose>
          <mass>0.301441</mass>
          <inertia>
            <ixx>0.0212961</ixx>
            <ixy>0.000127667</ixy>
            <ixz>-4.90947e-05</ixz>
            <iyy>0.0218228</iyy>
            <iyz>-2.69741e-05</iyz>
            <izz>0.0218584</izz>
          </inertia>
        </inertial>
        <collision name='neck_tilt_link_collision'>
          <pose frame=''>-0.04 -0.05 0 0 -0 0</pose>
          <geometry>
            <box>
              <size>0.1 0.03 0.05</size>
            </box>
          </geometry>
          <max_contacts>10</max_contacts>
          <surface>
            <contact>
              <ode/>
            </contact>
            <bounce/>
            <friction>
              <torsional>
                <ode/>
              </torsional>
              <ode/>
            </friction>
          </surface>
        </collision>
        <collision name='neck_tilt_link_fixed_joint_lump__face_shell_link_collision_1'>
          <pose frame=''>0 0 0 0 -0 0</pose>
          <geometry>
            <cylinder>
              <length>0.001</length>
              <radius>0.005</radius>
            </cylinder>
          </geometry>
          <max_contacts>10</max_contacts>
          <surface>
            <contact>
              <ode/>
            </contact>
            <bounce/>
            <friction>
              <torsional>
                <ode/>
              </torsional>
              <ode/>
            </friction>
          </surface>
        </collision>
        <collision name='neck_tilt_link_fixed_joint_lump__head_shell_link_collision_2'>
          <pose frame=''>0 0 0 0 -0 0</pose>
          <geometry>
            <cylinder>
              <length>0.001</length>
              <radius>0.005</radius>
            </cylinder>
          </geometry>
          <max_contacts>10</max_contacts>
          <surface>
            <contact>
              <ode/>
            </contact>
            <bounce/>
            <friction>
              <torsional>
                <ode/>
              </torsional>
              <ode/>
            </friction>
          </surface>
        </collision>
        <visual name='neck_tilt_link_visual'>
          <pose frame=''>-0.027 -0.027 0 0 -0 3.14159</pose>
          <geometry>
            <mesh>
              <scale>1 1 1</scale>
              <uri>/home/flash/catkin_ws/src/vizzy/vizzy_description/meshes/head/neck_tilt.dae</uri>
            </mesh>
          </geometry>
        </visual>
        <visual name='neck_tilt_link_fixed_joint_lump__face_shell_link_visual_1'>
          <pose frame=''>-0.394 0.69 0.0995 3.14159 1.57079 3.14159</pose>
          <geometry>
            <mesh>
              <scale>1 1 1</scale>
              <uri>/home/flash/catkin_ws/src/vizzy/vizzy_description/meshes/head/face.dae</uri>
            </mesh>
          </geometry>
        </visual>
        <visual name='neck_tilt_link_fixed_joint_lump__head_shell_link_visual_2'>
          <pose frame=''>0 0.41 0 -3.14159 1.57079 1.57079</pose>
          <geometry>
            <mesh>
              <scale>1 1 1</scale>
              <uri>/home/flash/catkin_ws/src/vizzy/vizzy_description/meshes/head/head.dae</uri>
            </mesh>
          </geometry>
        </visual>
        <self_collide>0</self_collide>
        <enable_wind>0</enable_wind>
        <kinematic>0</kinematic>
      </link>
      <joint name='neck_tilt_joint' type='revolute'>
        <child>neck_tilt_link</child>
        <parent>neck_pan_link</parent>
        <axis>
          <xyz>0 -1 0</xyz>
          <limit>
            <lower>-2.01416</lower>
            <upper>2.45772</upper>
            <effort>100</effort>
            <velocity>5</velocity>
          </limit>
          <dynamics>
            <damping>0</damping>
            <friction>5</friction>
            <spring_reference>0</spring_reference>
            <spring_stiffness>0</spring_stiffness>
          </dynamics>
          <use_parent_model_frame>1</use_parent_model_frame>
        </axis>
      </joint>
      <link name='eyes_tilt_link'>
        <pose frame=''>0.12379 0 0.99822 -1.5708 -0.369599 -0</pose>
        <inertial>
          <pose frame=''>-0.003738 -0.001068 -0.001068 0 0 -1.2012</pose>
          <mass>0.429223</mass>
          <inertia>
            <ixx>0.00336253</ixx>
            <ixy>-1.51155e-06</ixy>
            <ixz>-6.24898e-07</ixz>
            <iyy>0.00328657</iyy>
            <iyz>-3.71754e-06</iyz>
            <izz>0.00213784</izz>
          </inertia>
        </inertial>
        <collision name='eyes_tilt_link_collision'>
          <pose frame=''>-0.007 -0.002 -0.002 0 0 -1.2012</pose>
          <geometry>
            <cylinder>
              <length>0.07</length>
              <radius>0.02</radius>
            </cylinder>
          </geometry>
          <max_contacts>10</max_contacts>
          <surface>
            <contact>
              <ode/>
            </contact>
            <bounce/>
            <friction>
              <torsional>
                <ode/>
              </torsional>
              <ode/>
            </friction>
          </surface>
        </collision>
        <visual name='eyes_tilt_link_visual'>
          <pose frame=''>-0.007 -0.002 -0.002 0 0 -1.2012</pose>
          <geometry>
            <mesh>
              <scale>1 1 1</scale>
              <uri>/home/flash/catkin_ws/src/vizzy/vizzy_description/meshes/head/eyes_tilt.dae</uri>
            </mesh>
          </geometry>
        </visual>
        <self_collide>0</self_collide>
        <enable_wind>0</enable_wind>
        <kinematic>0</kinematic>
      </link>
      <joint name='eyes_tilt_joint' type='revolute'>
        <child>eyes_tilt_link</child>
        <parent>neck_tilt_link</parent>
        <axis>
          <xyz>-0 1 -0</xyz>
          <limit>
            <lower>-0.663225</lower>
            <upper>0.663225</upper>
            <effort>10</effort>
            <velocity>5</velocity>
          </limit>
          <dynamics>
            <damping>0</damping>
            <friction>5</friction>
            <spring_reference>0</spring_reference>
            <spring_stiffness>0</spring_stiffness>
          </dynamics>
          <use_parent_model_frame>1</use_parent_model_frame>
        </axis>
      </joint>
      <link name='l_eye_link'>
        <pose frame=''>0.12379 0.102 0.99822 -3.14159 -0 -3.14159</pose>
        <inertial>
          <pose frame=''>0 0 0 0 -0 1.5708</pose>
          <mass>0.158521</mass>
          <inertia>
            <ixx>0.000147615</ixx>
            <ixy>-1.56211e-09</ixy>
            <ixz>8.85545e-10</ixz>
            <iyy>0.00017784</iyy>
            <iyz>8.21234e-06</iyz>
            <izz>0.000144885</izz>
          </inertia>
        </inertial>
        <collision name='l_eye_link_collision'>
          <pose frame=''>0 0 0 0 -0 1.5708</pose>
          <geometry>
            <sphere>
              <radius>0.055</radius>
            </sphere>
          </geometry>
          <max_contacts>10</max_contacts>
          <surface>
            <contact>
              <ode/>
            </contact>
            <bounce/>
            <friction>
              <torsional>
                <ode/>
              </torsional>
              <ode/>
            </friction>
          </surface>
        </collision>
        <visual name='l_eye_link_visual'>
          <pose frame=''>0 0 0 0 -0 1.5708</pose>
          <geometry>
            <mesh>
              <scale>1 1 1</scale>
              <uri>/home/flash/catkin_ws/src/vizzy/vizzy_description/meshes/head/eye.dae</uri>
            </mesh>
          </geometry>
        </visual>
        <visual name='l_eye_link_fixed_joint_lump__l_camera_link_visual_1'>
          <pose frame=''>-0.0275 0 0 -3.14159 -0 3.14159</pose>
          <geometry>
            <box>
              <size>0.001 0.001 0.001</size>
            </box>
          </geometry>
          <material>
            <script>
              <uri>__default__</uri>
              <name>__default__</name>
            </script>
          </material>
        </visual>
        <visual name='l_eye_link_fixed_joint_lump__l_camera_vision_link_visual_2'>
          <pose frame=''>0 0 0 1.5708 0 -1.5708</pose>
          <geometry>
            <box>
              <size>0.001 0.001 0.001</size>
            </box>
          </geometry>
        </visual>
        <gravity>1</gravity>
        <velocity_decay/>
        <sensor name='l_camera' type='camera'>
          <update_rate>30</update_rate>
          <camera name='head'>
            <horizontal_fov>1.4912</horizontal_fov>
            <image>
              <width>320</width>
              <height>240</height>
              <format>R8G8B8</format>
            </image>
            <clip>
              <near>0.02</near>
              <far>300</far>
            </clip>
            <noise>
              <type>gaussian</type>
              <mean>0</mean>
              <stddev>0</stddev>
            </noise>
          </camera>
          <plugin name='camera_controller' filename='libgazebo_ros_camera.so'>
            <alwaysOn>1</alwaysOn>
            <updateRate>30.0</updateRate>
            <cameraName>vizzy/l_camera</cameraName>
            <imageTopicName>image_raw</imageTopicName>
            <cameraInfoTopicName>camera_info</cameraInfoTopicName>
            <frameName>l_camera_vision_link</frameName>
            <robotNamespace>/</robotNamespace>
          </plugin>
          <pose frame=''>-0.0275 0 0 -3.14159 -0 3.14159</pose>
        </sensor>
        <self_collide>0</self_collide>
        <enable_wind>0</enable_wind>
        <kinematic>0</kinematic>
      </link>
      <joint name='l_eye_joint' type='revolute'>
        <child>l_eye_link</child>
        <parent>eyes_tilt_link</parent>
        <axis>
          <xyz>-0 -0 -1</xyz>
          <limit>
            <lower>-1</lower>
            <upper>1</upper>
            <effort>1000</effort>
            <velocity>5</velocity>
          </limit>
          <dynamics>
            <damping>0</damping>
            <friction>5</friction>
            <spring_reference>0</spring_reference>
            <spring_stiffness>0</spring_stiffness>
          </dynamics>
          <use_parent_model_frame>1</use_parent_model_frame>
        </axis>
      </joint>
      <link name='r_eye_link'>
        <pose frame=''>0.12379 -0.102 0.99822 -3.14159 -0 -3.14159</pose>
        <inertial>
          <pose frame=''>0 0 0 0 -0 1.5708</pose>
          <mass>0.158521</mass>
          <inertia>
            <ixx>0.000147615</ixx>
            <ixy>-1.56211e-09</ixy>
            <ixz>8.85545e-10</ixz>
            <iyy>0.00017784</iyy>
            <iyz>8.21234e-06</iyz>
            <izz>0.000144885</izz>
          </inertia>
        </inertial>
        <collision name='r_eye_link_collision'>
          <pose frame=''>0 0 0 0 -0 1.5708</pose>
          <geometry>
            <sphere>
              <radius>0.055</radius>
            </sphere>
          </geometry>
          <max_contacts>10</max_contacts>
          <surface>
            <contact>
              <ode/>
            </contact>
            <bounce/>
            <friction>
              <torsional>
                <ode/>
              </torsional>
              <ode/>
            </friction>
          </surface>
        </collision>
        <visual name='r_eye_link_visual'>
          <pose frame=''>0 0 0 0 -0 1.5708</pose>
          <geometry>
            <mesh>
              <scale>1 1 1</scale>
              <uri>/home/flash/catkin_ws/src/vizzy/vizzy_description/meshes/head/eye.dae</uri>
            </mesh>
          </geometry>
        </visual>
        <visual name='r_eye_link_fixed_joint_lump__r_camera_link_visual_1'>
          <pose frame=''>-0.0275 0 0 -3.14159 -0 3.14159</pose>
          <geometry>
            <box>
              <size>0.001 0.001 0.001</size>
            </box>
          </geometry>
          <material>
            <script>
              <uri>__default__</uri>
              <name>__default__</name>
            </script>
          </material>
        </visual>
        <visual name='r_eye_link_fixed_joint_lump__r_camera_vision_link_visual_2'>
          <pose frame=''>0 0 0 1.5708 0 -1.5708</pose>
          <geometry>
            <box>
              <size>0.001 0.001 0.001</size>
            </box>
          </geometry>
        </visual>
        <gravity>1</gravity>
        <velocity_decay/>
        <sensor name='r_camera' type='camera'>
          <update_rate>30</update_rate>
          <camera name='head'>
            <horizontal_fov>1.4912</horizontal_fov>
            <image>
              <width>320</width>
              <height>240</height>
              <format>R8G8B8</format>
            </image>
            <clip>
              <near>0.02</near>
              <far>300</far>
            </clip>
            <noise>
              <type>gaussian</type>
              <mean>0</mean>
              <stddev>0</stddev>
            </noise>
          </camera>
          <plugin name='camera_controller' filename='libgazebo_ros_camera.so'>
            <alwaysOn>1</alwaysOn>
            <updateRate>30.0</updateRate>
            <cameraName>vizzy/r_camera</cameraName>
            <imageTopicName>image_raw</imageTopicName>
            <cameraInfoTopicName>camera_info</cameraInfoTopicName>
            <frameName>r_camera_vision_link</frameName>
            <robotNamespace>/</robotNamespace>
          </plugin>
          <pose frame=''>-0.0275 0 0 -3.14159 -0 3.14159</pose>
        </sensor>
        <self_collide>0</self_collide>
        <enable_wind>0</enable_wind>
        <kinematic>0</kinematic>
      </link>
      <joint name='r_eye_joint' type='revolute'>
        <child>r_eye_link</child>
        <parent>eyes_tilt_link</parent>
        <axis>
          <xyz>-0 -0 -1</xyz>
          <limit>
            <lower>-1</lower>
            <upper>1</upper>
            <effort>1000</effort>
            <velocity>5</velocity>
          </limit>
          <dynamics>
            <damping>0</damping>
            <friction>5</friction>
            <spring_reference>0</spring_reference>
            <spring_stiffness>0</spring_stiffness>
          </dynamics>
          <use_parent_model_frame>1</use_parent_model_frame>
        </axis>
      </joint>
      <link name='r_shoulder_scapula_link'>
        <pose frame=''>0 -0.0805 0.58067 0 -0.0175 0</pose>
        <inertial>
          <pose frame=''>0 0 0.16 3.14159 -0 0</pose>
          <mass>0.328838</mass>
          <inertia>
            <ixx>0.00123108</ixx>
            <ixy>-7.89159e-11</ixy>
            <ixz>6.34905e-10</ixz>
            <iyy>0.000919899</iyy>
            <iyz>7.50425e-05</iyz>
            <izz>0.000480034</izz>
          </inertia>
        </inertial>
        <collision name='r_shoulder_scapula_link_collision'>
          <pose frame=''>0 0 0.1 3.14159 -0 0</pose>
          <geometry>
            <cylinder>
              <length>0.11</length>
              <radius>0.027</radius>
            </cylinder>
          </geometry>
          <max_contacts>10</max_contacts>
          <surface>
            <contact>
              <ode/>
            </contact>
            <bounce/>
            <friction>
              <torsional>
                <ode/>
              </torsional>
              <ode/>
            </friction>
          </surface>
        </collision>
        <visual name='r_shoulder_scapula_link_visual'>
          <pose frame=''>0 0 0.16 3.14159 -0 0</pose>
          <geometry>
            <mesh>
              <scale>1 1 1</scale>
              <uri>/home/flash/catkin_ws/src/vizzy/vizzy_description/meshes/arm/r_shoulder_scapula.dae</uri>
            </mesh>
          </geometry>
        </visual>
        <self_collide>0</self_collide>
        <enable_wind>0</enable_wind>
        <kinematic>0</kinematic>
      </link>
      <joint name='r_shoulder_scapula_joint' type='revolute'>
        <child>r_shoulder_scapula_link</child>
        <parent>waist_link</parent>
        <axis>
          <xyz>-0.017499 -0 0.999847</xyz>
          <limit>
            <lower>-0.314159</lower>
            <upper>0.314159</upper>
            <effort>10</effort>
            <velocity>3</velocity>
          </limit>
          <dynamics>
            <damping>0</damping>
            <friction>0.1</friction>
            <spring_reference>0</spring_reference>
            <spring_stiffness>0</spring_stiffness>
          </dynamics>
          <use_parent_model_frame>1</use_parent_model_frame>
        </axis>
      </joint>
      <link name='r_shoulder_flection_link'>
        <pose frame=''>-0.00371 -0.0805 0.792638 1.5708 -0.0175 0</pose>
        <inertial>
          <pose frame=''>0 0 0.048 3.14159 -0 2.08689</pose>
          <mass>0.329708</mass>
          <inertia>
            <ixx>0.00116793</ixx>
            <ixy>-0.00013489</ixy>
            <ixz>3.78931e-05</ixz>
            <iyy>0.00101232</iyy>
            <iyz>-6.56608e-05</iyz>
            <izz>0.000480379</izz>
          </inertia>
        </inertial>
        <collision name='r_shoulder_flection_link_collision'>
          <pose frame=''>0 0 0.02 3.14159 -0 2.08689</pose>
          <geometry>
            <cylinder>
              <length>0.1</length>
              <radius>0.025</radius>
            </cylinder>
          </geometry>
          <max_contacts>10</max_contacts>
          <surface>
            <contact>
              <ode/>
            </contact>
            <bounce/>
            <friction>
              <torsional>
                <ode/>
              </torsional>
              <ode/>
            </friction>
          </surface>
        </collision>
        <visual name='r_shoulder_flection_link_visual'>
          <pose frame=''>0 0 0.048 3.14159 -0 2.08689</pose>
          <geometry>
            <mesh>
              <scale>1 1 1</scale>
              <uri>/home/flash/catkin_ws/src/vizzy/vizzy_description/meshes/arm/r_shoulder_flection.dae</uri>
            </mesh>
          </geometry>
        </visual>
        <self_collide>0</self_collide>
        <enable_wind>0</enable_wind>
        <kinematic>0</kinematic>
      </link>
      <joint name='r_shoulder_flection_joint' type='revolute'>
        <child>r_shoulder_flection_link</child>
        <parent>r_shoulder_scapula_link</parent>
        <axis>
          <xyz>0 -1 -0</xyz>
          <limit>
            <lower>-1.309</lower>
            <upper>2.35619</upper>
            <effort>10</effort>
            <velocity>3</velocity>
          </limit>
          <dynamics>
            <damping>0</damping>
            <friction>0.1</friction>
            <spring_reference>0</spring_reference>
            <spring_stiffness>0</spring_stiffness>
          </dynamics>
          <use_parent_model_frame>1</use_parent_model_frame>
        </axis>
      </joint>
      <link name='r_shoulder_abduction_link'>
        <pose frame=''>-0.00371 -0.18306 0.792638 -3.14159 1.5533 -0</pose>
        <inertial>
          <pose frame=''>0.034 0.009 -0.001 -3.14159 0 1.91989</pose>
          <mass>0.337952</mass>
          <inertia>
            <ixx>0.000722844</ixx>
            <ixy>-4.62402e-05</ixy>
            <ixz>-1.45397e-06</ixz>
            <iyy>0.000316567</iyy>
            <iyz>1.40156e-05</iyz>
            <izz>0.00057776</izz>
          </inertia>
        </inertial>
        <collision name='r_shoulder_abduction_link_collision'>
          <pose frame=''>0 0 0 -3.14159 0 1.91989</pose>
          <geometry>
            <cylinder>
              <length>0.11</length>
              <radius>0.028</radius>
            </cylinder>
          </geometry>
          <max_contacts>10</max_contacts>
          <surface>
            <contact>
              <ode/>
            </contact>
            <bounce/>
            <friction>
              <torsional>
                <ode/>
              </torsional>
              <ode/>
            </friction>
          </surface>
        </collision>
        <visual name='r_shoulder_abduction_link_visual'>
          <pose frame=''>0.034 0.009 -0.001 -3.14159 0 1.91989</pose>
          <geometry>
            <mesh>
              <scale>1 1 1</scale>
              <uri>/home/flash/catkin_ws/src/vizzy/vizzy_description/meshes/arm/r_shoulder_abduction.dae</uri>
            </mesh>
          </geometry>
        </visual>
        <self_collide>0</self_collide>
        <enable_wind>0</enable_wind>
        <kinematic>0</kinematic>
      </link>
      <joint name='r_shoulder_abduction_joint' type='revolute'>
        <child>r_shoulder_abduction_link</child>
        <parent>r_shoulder_flection_link</parent>
        <axis>
          <xyz>-0.999847 0 -0.017499</xyz>
          <limit>
            <lower>0</lower>
            <upper>1.309</upper>
            <effort>10</effort>
            <velocity>3</velocity>
          </limit>
          <dynamics>
            <damping>0</damping>
            <friction>0.1</friction>
            <spring_reference>0</spring_reference>
            <spring_stiffness>0</spring_stiffness>
          </dynamics>
          <use_parent_model_frame>1</use_parent_model_frame>
        </axis>
      </joint>
      <link name='r_shoulder_rotation_link'>
        <pose frame=''>-0.00371 -0.18306 0.792638 -3.12297 -0.34901 -1.57717</pose>
        <inertial>
          <pose frame=''>-0.003 0.006 0.127 -3.14159 -0 1.5708</pose>
          <mass>0.302328</mass>
          <inertia>
            <ixx>0.000615246</ixx>
            <ixy>4.12484e-06</ixy>
            <ixz>6.13277e-05</ixz>
            <iyy>0.000574849</iyy>
            <iyz>-2.49115e-05</iyz>
            <izz>0.000240227</izz>
          </inertia>
        </inertial>
        <collision name='r_shoulder_rotation_link_collision'>
          <pose frame=''>0 0 0.08 -3.14159 -0 1.5708</pose>
          <geometry>
            <cylinder>
              <length>0.09</length>
              <radius>0.028</radius>
            </cylinder>
          </geometry>
          <max_contacts>10</max_contacts>
          <surface>
            <contact>
              <ode/>
            </contact>
            <bounce/>
            <friction>
              <torsional>
                <ode/>
              </torsional>
              <ode/>
            </friction>
          </surface>
        </collision>
        <visual name='r_shoulder_rotation_link_visual'>
          <pose frame=''>-0.003 0.006 0.127 -3.14159 -0 1.5708</pose>
          <geometry>
            <mesh>
              <scale>1 1 1</scale>
              <uri>/home/flash/catkin_ws/src/vizzy/vizzy_description/meshes/arm/r_shoulder_rotation.dae</uri>
            </mesh>
          </geometry>
        </visual>
        <self_collide>0</self_collide>
        <enable_wind>0</enable_wind>
        <kinematic>0</kinematic>
      </link>
      <joint name='r_shoulder_rotation_joint' type='revolute'>
        <child>r_shoulder_rotation_link</child>
        <parent>r_shoulder_abduction_link</parent>
        <axis>
          <xyz>0.016444 -0.34202 -0.939549</xyz>
          <limit>
            <lower>-1.48353</lower>
            <upper>1.48353</upper>
            <effort>10</effort>
            <velocity>3</velocity>
          </limit>
          <dynamics>
            <damping>0</damping>
            <friction>0.1</friction>
            <spring_reference>0</spring_reference>
            <spring_stiffness>0</spring_stiffness>
          </dynamics>
          <use_parent_model_frame>1</use_parent_model_frame>
        </axis>
      </joint>
      <link name='r_elbow_flection_link'>
        <pose frame=''>-0.00103 -0.238796 0.639529 -1.22173 0.0175 3.14159</pose>
        <inertial>
          <pose frame=''>-0.002 0.035 0 0 -0 0.0873</pose>
          <mass>0.302328</mass>
          <inertia>
            <ixx>0.000615246</ixx>
            <ixy>4.12484e-06</ixy>
            <ixz>6.13277e-05</ixz>
            <iyy>0.000574849</iyy>
            <iyz>-2.49115e-05</iyz>
            <izz>0.000240227</izz>
          </inertia>
        </inertial>
        <collision name='r_elbow_flection_link_collision'>
          <pose frame=''>0 0 0 0 -0 0</pose>
          <geometry>
            <cylinder>
              <length>0.07</length>
              <radius>0.025</radius>
            </cylinder>
          </geometry>
          <max_contacts>10</max_contacts>
          <surface>
            <contact>
              <ode/>
            </contact>
            <bounce/>
            <friction>
              <torsional>
                <ode/>
              </torsional>
              <ode/>
            </friction>
          </surface>
        </collision>
        <visual name='r_elbow_flection_link_visual'>
          <pose frame=''>-0.002 0.035 0 0 -0 0.0873</pose>
          <geometry>
            <mesh>
              <scale>1 1 1</scale>
              <uri>/home/flash/catkin_ws/src/vizzy/vizzy_description/meshes/arm/r_elbow_flection.dae</uri>
            </mesh>
          </geometry>
        </visual>
        <self_collide>0</self_collide>
        <enable_wind>0</enable_wind>
        <kinematic>0</kinematic>
      </link>
      <joint name='r_elbow_flection_joint' type='revolute'>
        <child>r_elbow_flection_link</child>
        <parent>r_shoulder_rotation_link</parent>
        <axis>
          <xyz>-0.005985 -0.939693 0.341968</xyz>
          <limit>
            <lower>0</lower>
            <upper>1.91986</upper>
            <effort>10</effort>
            <velocity>3</velocity>
          </limit>
          <dynamics>
            <damping>0</damping>
            <friction>0.1</friction>
            <spring_reference>0</spring_reference>
            <spring_stiffness>0</spring_stiffness>
          </dynamics>
          <use_parent_model_frame>1</use_parent_model_frame>
        </axis>
      </joint>
      <link name='r_forearm_pronation_link'>
        <pose frame=''>-0.00103 -0.238796 0.639529 0.35082 0.099515 -3.11162</pose>
        <inertial>
          <pose frame=''>0 -0.007 -0.11 0 -0 1.5708</pose>
          <mass>0.192525</mass>
          <inertia>
            <ixx>0.000215803</ixx>
            <ixy>6.01824e-08</ixy>
            <ixz>-9.78526e-06</ixz>
            <iyy>0.000229048</iyy>
            <iyz>-3.21836e-07</iyz>
            <izz>0.000102659</izz>
          </inertia>
        </inertial>
        <collision name='r_forearm_pronation_link_collision'>
          <pose frame=''>0 0 -0.09 0 -0 0</pose>
          <geometry>
            <cylinder>
              <length>0.1</length>
              <radius>0.025</radius>
            </cylinder>
          </geometry>
          <max_contacts>10</max_contacts>
          <surface>
            <contact>
              <ode/>
            </contact>
            <bounce/>
            <friction>
              <torsional>
                <ode/>
              </torsional>
              <ode/>
            </friction>
          </surface>
        </collision>
        <visual name='r_forearm_pronation_link_visual'>
          <pose frame=''>0 -0.007 -0.11 0 -0 1.5708</pose>
          <geometry>
            <mesh>
              <scale>1 1 1</scale>
              <uri>/home/flash/catkin_ws/src/vizzy/vizzy_description/meshes/arm/r_forearm_pronation.dae</uri>
            </mesh>
          </geometry>
        </visual>
        <self_collide>0</self_collide>
        <enable_wind>0</enable_wind>
        <kinematic>0</kinematic>
      </link>
      <joint name='r_forearm_pronation_joint' type='revolute'>
        <child>r_forearm_pronation_link</child>
        <parent>r_elbow_flection_link</parent>
        <axis>
          <xyz>-0.103557 0.340718 0.934445</xyz>
          <limit>
            <lower>-1.48353</lower>
            <upper>1.48353</upper>
            <effort>10</effort>
            <velocity>3</velocity>
          </limit>
          <dynamics>
            <damping>0</damping>
            <friction>0.1</friction>
            <spring_reference>0</spring_reference>
            <spring_stiffness>0</spring_stiffness>
          </dynamics>
          <use_parent_model_frame>1</use_parent_model_frame>
        </axis>
      </joint>
      <link name='r_wrist_abduction_link'>
        <pose frame=''>0.018568 -0.303276 0.462685 1.92162 0.099515 -3.11162</pose>
        <inertial>
          <pose frame=''>0.0047 0.028 -0.003 0 -0 3.14159</pose>
          <mass>0.151303</mass>
          <inertia>
            <ixx>0.000116374</ixx>
            <ixy>1.3101e-05</ixy>
            <ixz>6.69704e-05</ixz>
            <iyy>0.000200316</iyy>
            <iyz>1.00269e-05</iyz>
            <izz>0.000162164</izz>
          </inertia>
        </inertial>
        <collision name='r_wrist_abduction_link_collision'>
          <pose frame=''>0 0 0 3.14159 1.57079 3e-06</pose>
          <geometry>
            <cylinder>
              <length>0.06</length>
              <radius>0.025</radius>
            </cylinder>
          </geometry>
          <max_contacts>10</max_contacts>
          <surface>
            <contact>
              <ode/>
            </contact>
            <bounce/>
            <friction>
              <torsional>
                <ode/>
              </torsional>
              <ode/>
            </friction>
          </surface>
        </collision>
        <visual name='r_wrist_abduction_link_visual'>
          <pose frame=''>0.0047 0.028 -0.003 0 -0 3.14159</pose>
          <geometry>
            <mesh>
              <scale>1 1 1</scale>
              <uri>/home/flash/catkin_ws/src/vizzy/vizzy_description/meshes/arm/r_wrist_abduction.dae</uri>
            </mesh>
          </geometry>
        </visual>
        <self_collide>0</self_collide>
        <enable_wind>0</enable_wind>
        <kinematic>0</kinematic>
      </link>
      <joint name='r_wrist_abduction_joint' type='revolute'>
        <child>r_wrist_abduction_link</child>
        <parent>r_forearm_pronation_link</parent>
        <axis>
          <xyz>0.005985 0.939693 -0.341968</xyz>
          <limit>
            <lower>-0.610865</lower>
            <upper>0.610865</upper>
            <effort>10</effort>
            <velocity>3</velocity>
          </limit>
          <dynamics>
            <damping>0</damping>
            <friction>0.1</friction>
            <spring_reference>0</spring_reference>
            <spring_stiffness>0</spring_stiffness>
          </dynamics>
          <use_parent_model_frame>1</use_parent_model_frame>
        </axis>
      </joint>
      <link name='r_wrist_flection_link'>
        <pose frame=''>0.018568 -0.303276 0.462685 -1.28805 1.2067 -1.27573</pose>
        <inertial>
          <pose frame=''>0.106 0.0077 0.017 -3.14159 -0 1.5708</pose>
          <mass>0.263178</mass>
          <inertia>
            <ixx>0.00141537</ixx>
            <ixy>-5.47007e-06</ixy>
            <ixz>4.93142e-05</ixz>
            <iyy>0.000423838</iyy>
            <iyz>0.000132116</iyz>
            <izz>0.00103376</izz>
          </inertia>
        </inertial>
        <collision name='r_wrist_flection_link_collision'>
          <pose frame=''>0.106 0.0077 0 0 -0 0</pose>
          <geometry>
            <box>
              <size>0.11 0.015 0.1</size>
            </box>
          </geometry>
          <max_contacts>10</max_contacts>
          <surface>
            <contact>
              <ode/>
            </contact>
            <bounce/>
            <friction>
              <torsional>
                <ode/>
              </torsional>
              <ode/>
            </friction>
          </surface>
        </collision>
        <visual name='r_wrist_flection_link_visual'>
          <pose frame=''>0.106 0.0077 0.017 -3.14159 -0 1.5708</pose>
          <geometry>
            <mesh>
              <scale>1 1 1</scale>
              <uri>/home/flash/catkin_ws/src/vizzy/vizzy_description/meshes/arm/r_wrist_flection_simple.dae</uri>
            </mesh>
          </geometry>
        </visual>
        <self_collide>0</self_collide>
        <enable_wind>0</enable_wind>
        <kinematic>0</kinematic>
      </link>
      <joint name='r_wrist_flection_joint' type='revolute'>
        <child>r_wrist_flection_link</child>
        <parent>r_wrist_abduction_link</parent>
        <axis>
          <xyz>0.994606 0.02982 0.099351</xyz>
          <limit>
            <lower>-0.610865</lower>
            <upper>0.610865</upper>
            <effort>10</effort>
            <velocity>3</velocity>
          </limit>
          <dynamics>
            <damping>0</damping>
            <friction>0.1</friction>
            <spring_reference>0</spring_reference>
            <spring_stiffness>0</spring_stiffness>
          </dynamics>
          <use_parent_model_frame>1</use_parent_model_frame>
        </axis>
      </joint>
      <plugin name='differential_drive_controller' filename='libgazebo_ros_diff_drive.so'>
        <leftJoint>r_wheel_joint</leftJoint>
        <rightJoint>l_wheel_joint</rightJoint>
        <wheelSeparation>0.490</wheelSeparation>
        <wheelDiameter>0.39628</wheelDiameter>
        <torque>20</torque>
        <legacyMode>1</legacyMode>
        <updateRate>100</updateRate>
        <commandTopic>vizzy/cmd_vel</commandTopic>
        <odometryTopic>odom</odometryTopic>
        <odometryFrame>odom</odometryFrame>
        <robotBaseFrame>base_footprint</robotBaseFrame>
        <publishOdomTF>1</publishOdomTF>
        <odometrySource>encoder</odometrySource>
        <wheelTorque>10</wheelTorque>
        <wheelAcceleration>0</wheelAcceleration>
        <publishTf>1</publishTf>
        <publishWheelTF>1</publishWheelTF>
        <publishWheelJointState>1</publishWheelJointState>
        <rosDebugLevel>na</rosDebugLevel>
        <robotNamespace>/</robotNamespace>
      </plugin>
      <static>0</static>
      <plugin name='gazebo_ros_control' filename='libgazebo_ros_control.so'>
        <robotNamespace>/vizzy</robotNamespace>
      </plugin>
      <pose frame=''>0 0 0 0 -0 3.1415</pose>
    </model>
    <model name='pessoa1'>
      <static>0</static>
      <link name='base'>
        <pose frame=''>0 0 0 0 -0 0</pose>
        <collision name='collision'>
          <geometry>
            <mesh>
              <uri>model://pessoa1/meshes/models/citizen_female.dae</uri>
              <scale>0.4 0.4 0.4</scale>
            </mesh>
          </geometry>
          <max_contacts>10</max_contacts>
          <surface>
            <contact>
              <ode/>
            </contact>
            <bounce/>
            <friction>
              <torsional>
                <ode/>
              </torsional>
              <ode/>
            </friction>
          </surface>
        </collision>
        <visual name='visual'>
          <pose frame=''>0 0 0 0 -0 0</pose>
          <geometry>
            <mesh>
              <uri>model://pessoa1/meshes/models/citizen_female.dae</uri>
              <scale>0.4 0.4 0.4</scale>
            </mesh>
          </geometry>
        </visual>
        <self_collide>0</self_collide>
        <inertial>
          <pose frame=''>0 0 0 0 -0 0</pose>
          <inertia>
            <ixx>1</ixx>
            <ixy>0</ixy>
            <ixz>0</ixz>
            <iyy>1</iyy>
            <iyz>0</iyz>
            <izz>1</izz>
          </inertia>
          <mass>1</mass>
        </inertial>
        <enable_wind>0</enable_wind>
        <kinematic>0</kinematic>
      </link>
      <pose frame=''>-1.91289 2.00544 0 0 -0 0</pose>
    </model>
    <model name='pessoa2'>
      <static>0</static>
      <link name='base'>
        <pose frame=''>0 0 0 0 -0 0</pose>
        <collision name='collision'>
          <geometry>
            <mesh>
              <uri>model://pessoa2/meshes/models/citizen_male.dae</uri>
              <scale>0.4 0.4 0.4</scale>
            </mesh>
          </geometry>
          <max_contacts>10</max_contacts>
          <surface>
            <contact>
              <ode/>
            </contact>
            <bounce/>
            <friction>
              <torsional>
                <ode/>
              </torsional>
              <ode/>
            </friction>
          </surface>
        </collision>
        <visual name='visual'>
          <pose frame=''>0 0 0 0 -0 0</pose>
          <geometry>
            <mesh>
              <uri>model://pessoa2/meshes/models/citizen_male.dae</uri>
              <scale>0.4 0.4 0.4</scale>
            </mesh>
          </geometry>
        </visual>
        <self_collide>0</self_collide>
        <inertial>
          <pose frame=''>0 0 0 0 -0 0</pose>
          <inertia>
            <ixx>1</ixx>
            <ixy>0</ixy>
            <ixz>0</ixz>
            <iyy>1</iyy>
            <iyz>0</iyz>
            <izz>1</izz>
          </inertia>
          <mass>1</mass>
        </inertial>
        <enable_wind>0</enable_wind>
        <kinematic>0</kinematic>
      </link>
      <pose frame=''>-2.86165 1.11402 0 0 -0 0</pose>
    </model>
    <state world_name='default'>
      <sim_time>33 632000000</sim_time>
      <real_time>152 119985233</real_time>
      <wall_time>1588680557 473753720</wall_time>
      <iterations>16816</iterations>
      <model name='7thmap'>
        <pose frame=''>9 -10 0 0 -0 0</pose>
        <scale>1 1 1</scale>
        <link name='body'>
          <pose frame=''>9 -10 0 0 -0 0</pose>
          <velocity>0 0 0 0 -0 0</velocity>
          <acceleration>0 0 0 0 -0 0</acceleration>
          <wrench>0 0 0 0 -0 0</wrench>
        </link>
      </model>
      <model name='docking_base'>
        <pose frame=''>0 0 0 0 -0 0</pose>
        <scale>1 1 1</scale>
        <link name='docking_pattern'>
          <pose frame=''>2 0 0 0 -0 0</pose>
          <velocity>0 0 0 0 -0 0</velocity>
          <acceleration>0 0 0 0 -0 0</acceleration>
          <wrench>0 0 0 0 -0 0</wrench>
        </link>
      </model>
      <model name='pessoa1'>
        <pose frame=''>-1.91303 2.00543 0.001055 0.008979 -0.104011 -0.001181</pose>
        <scale>1 1 1</scale>
        <link name='base'>
          <pose frame=''>-1.91303 2.00543 0.001055 0.008979 -0.104011 -0.001181</pose>
          <velocity>3.6e-05 9.6e-05 0.005516 -0.092125 0.034565 -0</velocity>
          <acceleration>0.000263 0.000177 -4.82256 0.324006 0.069341 -2e-05</acceleration>
          <wrench>0.000263 0.000177 -4.82256 0 -0 0</wrench>
        </link>
      </model>
      <model name='pessoa2'>
        <pose frame=''>-2.86152 1.11405 0.010971 0.011889 0.002078 1.65564</pose>
        <scale>1 1 1</scale>
        <link name='base'>
          <pose frame=''>-2.86152 1.11405 0.010971 0.011889 0.002078 1.65564</pose>
          <velocity>0 0 0 0 -0 0</velocity>
          <acceleration>0.01233 -0.006366 -0.169667 0.57063 1.14359 2.5e-05</acceleration>
          <wrench>0.01233 -0.006366 -0.169667 0 -0 0</wrench>
        </link>
      </model>
      <model name='vizzy'>
        <pose frame=''>-0.000138 -1e-06 -1.9e-05 0 -0 3.14148</pose>
        <scale>1 1 1</scale>
        <link name='base_footprint'>
          <pose frame=''>-0.000138 -1e-06 -1.9e-05 0 -0 3.14148</pose>
          <velocity>-5e-06 0 1.5e-05 0 -0 0</velocity>
          <acceleration>-8.2e-05 0.000812 -1.6e-05 -3.7e-05 -1e-06 -4.4e-05</acceleration>
          <wrench>-0.005067 0.050119 -0.00097 0 -0 0</wrench>
        </link>
        <link name='eyes_tilt_link'>
          <pose frame=''>-0.123876 -6.6e-05 0.998318 -1.57079 -0.370548 -3.14103</pose>
          <velocity>-6e-06 -0 1.5e-05 -2e-06 -1e-06 0</velocity>
          <acceleration>-3.1e-05 7e-05 3.3e-05 -0.00117 0.000738 0.00098</acceleration>
          <wrench>-1.3e-05 3e-05 1.4e-05 0 -0 0</wrench>
        </link>
        <link name='l_elbow_flection_link'>
          <pose frame=''>0.009074 -0.238776 0.639569 1.91993 0.03332 -3.13551</pose>
          <velocity>3.6e-05 4e-06 1.4e-05 1.2e-05 1.3e-05 -0.00079</velocity>
          <acceleration>0.026555 -0.002417 0.003583 -0.382708 -1.10618 -0.250779</acceleration>
          <wrench>0.008028 -0.000731 0.001083 0 -0 0</wrench>
        </link>
        <link name='l_eye_link'>
          <pose frame=''>-0.123818 -0.102066 0.998318 3.14159 0.000949 0.000567</pose>
          <velocity>-6e-06 -0 1.5e-05 -2e-06 -1e-06 0</velocity>
          <acceleration>0.000129 6.5e-05 0.000154 -0.00131 0.000466 0.00169</acceleration>
          <wrench>2e-05 1e-05 2.4e-05 0 -0 0</wrench>
        </link>
        <link name='l_forearm_pronation_link'>
          <pose frame=''>0.009074 -0.238772 0.639567 -2.79172 -0.044634 3.10658</pose>
          <velocity>4.1e-05 2.5e-05 7e-06 -0.000201 4.2e-05 -0.000822</velocity>
          <acceleration>0.000938 -0.003591 0.005598 -0.214837 -0.4706 2.98599</acceleration>
          <wrench>0.000181 -0.000691 0.001078 0 -0 0</wrench>
        </link>
        <link name='l_shoulder_abduction_link'>
          <pose frame=''>0.003633 -0.183063 0.792614 3.13872 -1.53543 -3.13824</pose>
          <velocity>-1.1e-05 -1e-06 1.4e-05 5e-06 -0.000256 0.000244</velocity>
          <acceleration>0.003561 0.000238 0.001482 -0.970522 0.58115 1.54964</acceleration>
          <wrench>0.001203 8e-05 0.000501 0 -0 0</wrench>
        </link>
        <link name='l_shoulder_flection_link'>
          <pose frame=''>0.003585 -0.080504 0.792618 -1.57073 -0.035366 0.000476</pose>
          <velocity>-1.4e-05 -1e-06 1.5e-05 2e-06 -0.000217 9e-05</velocity>
          <acceleration>-0.005267 0.000721 0.000582 2.06715 1.17552 1.19765</acceleration>
          <wrench>-0.001736 0.000238 0.000192 0 -0 0</wrench>
        </link>
        <link name='l_shoulder_rotation_link'>
          <pose frame=''>0.003633 -0.183059 0.792612 -0.035457 0.348944 1.56475</pose>
          <velocity>-1.3e-05 4e-06 1.2e-05 2e-05 -0.000534 -0.000557</velocity>
          <acceleration>0.029233 -0.002962 0.004978 -1.46464 -0.022348 -1.50756</acceleration>
          <wrench>0.008838 -0.000896 0.001505 0 -0 0</wrench>
        </link>
        <link name='l_shoulder_scapula_link'>
          <pose frame=''>-0.000147 -0.080499 0.580651 -3.14155 0.017603 0.000479</pose>
          <velocity>-1.3e-05 -0 1.5e-05 3e-06 2.7e-05 1.1e-05</velocity>
          <acceleration>-0.003209 0.00082 3.1e-05 3.03175 -0.001875 0.052973</acceleration>
          <wrench>-0.001055 0.00027 1e-05 0 -0 0</wrench>
        </link>
        <link name='l_wheel_link'>
          <pose frame=''>-0.003759 -0.245 0.198121 1.5708 1.57009 -9.9e-05</pose>
          <velocity>-5e-06 0 1.5e-05 -2e-06 -2.3e-05 0</velocity>
          <acceleration>-6e-05 0.000649 -6e-06 -0.003228 -0.000154 0.000168</acceleration>
          <wrench>-0.000302 0.003246 -3.1e-05 0 -0 0</wrench>
        </link>
        <link name='l_wrist_abduction_link'>
          <pose frame=''>-0.001125 -0.303326 0.46196 -1.22119 -0.027852 3.1127</pose>
          <velocity>-6.9e-05 -0.000105 8.3e-05 -0.004829 0.00155 -0.000955</velocity>
          <acceleration>-0.030876 -8.4e-05 0.006515 2.06178 -1.20486 1.17849</acceleration>
          <wrench>-0.004672 -1.3e-05 0.000986 0 -0 0</wrench>
        </link>
        <link name='l_wrist_flection_link'>
          <pose frame=''>-0.001126 -0.303327 0.461961 1.65113 -1.2162 1.46655</pose>
          <velocity>-1.5e-05 -3e-05 2.6e-05 0.001005 -0.000446 -0.00057</velocity>
          <acceleration>-0.012354 -0.026886 0.011267 2.97851 1.54977 2.6379</acceleration>
          <wrench>-0.003251 -0.007076 0.002965 0 -0 0</wrench>
        </link>
        <link name='neck_pan_link'>
          <pose frame=''>-0.000167 1e-06 0.580651 3.14159 9.4e-05 0.000573</pose>
          <velocity>-6e-06 -1e-06 1.5e-05 -2e-06 -1e-06 -5e-06</velocity>
          <acceleration>-4.6e-05 0.000158 -2e-05 -0.001087 0.000447 -0.002095</acceleration>
          <wrench>-1e-05 3.5e-05 -5e-06 0 -0 0</wrench>
        </link>
        <link name='neck_tilt_link'>
          <pose frame=''>-0.000131 3e-06 0.95065 -1.57081 0.000949 0.000567</pose>
          <velocity>-6e-06 -0 1.5e-05 -2e-06 -1e-06 0</velocity>
          <acceleration>-3.9e-05 0.000194 -8e-06 -0.001142 0.000461 0.001564</acceleration>
          <wrench>-1.2e-05 5.8e-05 -3e-06 0 -0 0</wrench>
        </link>
        <link name='r_elbow_flection_link'>
          <pose frame=''>0.009889 0.23878 0.639603 -1.2223 -0.044643 0.011491</pose>
          <velocity>-4e-06 -1e-06 1.4e-05 -1.9e-05 -6.1e-05 0.000303</velocity>
          <acceleration>-0.000342 0.000615 -0.000461 2.30354 1.19409 -1.09889</acceleration>
          <wrench>-0.000103 0.000186 -0.00014 0 -0 0</wrench>
        </link>
        <link name='r_eye_link'>
          <pose frame=''>-0.123933 0.101934 0.998317 3.14159 0.000949 0.000613</pose>
          <velocity>-6e-06 -0 1.5e-05 -2e-06 -1e-06 0</velocity>
          <acceleration>-0.00019 6.5e-05 -8.1e-05 -0.001306 0.000466 0.001704</acceleration>
          <wrench>-3e-05 1e-05 -1.3e-05 0 -0 0</wrench>
        </link>
        <link name='r_forearm_pronation_link'>
          <pose frame=''>0.009889 0.238776 0.639601 0.348389 0.037358 0.041445</pose>
          <velocity>-4e-06 -1e-06 1.4e-05 -1.9e-05 -6.3e-05 0.000306</velocity>
          <acceleration>-0.000129 0.000217 -0.000617 -0.886398 0.376074 1.55741</acceleration>
          <wrench>-2.5e-05 4.2e-05 -0.000119 0 -0 0</wrench>
        </link>
        <link name='r_shoulder_abduction_link'>
          <pose frame=''>0.003637 0.18306 0.792614 -0.000704 1.53008 -0.00105</pose>
          <velocity>-5e-06 1e-06 1.4e-05 -3e-06 -9e-06 6e-06</velocity>
          <acceleration>-0.000748 0.001146 -0.000227 1.80428 1.1059 -0.616451</acceleration>
          <wrench>-0.000253 0.000387 -7.7e-05 0 -0 0</wrench>
        </link>
        <link name='r_shoulder_flection_link'>
          <pose frame=''>0.003602 0.080502 0.792616 1.57082 0.04071 3.14125</pose>
          <velocity>-6e-06 1e-06 1.5e-05 1e-06 -8e-06 -1.6e-05</velocity>
          <acceleration>-0.000548 0.001231 -0.000137 0.406433 -0.721894 0.792884</acceleration>
          <wrench>-0.000181 0.000406 -4.5e-05 0 -0 0</wrench>
        </link>
        <link name='r_shoulder_rotation_link'>
          <pose frame=''>0.003637 0.183055 0.792612 3.09376 -0.348147 1.59849</pose>
          <velocity>-5e-06 0 1.4e-05 -1.6e-05 -0.00011 0.000284</velocity>
          <acceleration>-0.000496 0.000849 -0.000335 -1.19028 -0.258311 -0.715652</acceleration>
          <wrench>-0.00015 0.000257 -0.000101 0 -0 0</wrench>
        </link>
        <link name='r_shoulder_scapula_link'>
          <pose frame=''>-0.00013 0.080503 0.580651 1e-06 -0.017607 3.14125</pose>
          <velocity>-3e-06 1e-06 1.5e-05 -2e-06 -1.1e-05 -0.000135</velocity>
          <acceleration>-0.000153 0.001222 -1.4e-05 1.99632 -1.02067 -0.888351</acceleration>
          <wrench>-5e-05 0.000402 -5e-06 0 -0 0</wrench>
        </link>
        <link name='r_wheel_link'>
          <pose frame=''>-0.003706 0.245 0.198121 1.5708 1.57012 -9.9e-05</pose>
          <velocity>-5e-06 0 1.5e-05 -2e-06 -2.2e-05 0</velocity>
          <acceleration>-4.7e-05 0.000652 -2.3e-05 -0.003239 -0.00012 0.000156</acceleration>
          <wrench>-0.000235 0.003258 -0.000117 0 -0 0</wrench>
        </link>
        <link name='r_wrist_abduction_link'>
          <pose frame=''>0.000574 0.303051 0.461844 1.91908 0.029766 0.038687</pose>
          <velocity>-1.3e-05 -7e-06 1.2e-05 -1.8e-05 -0.000143 0.000277</velocity>
          <acceleration>-7.9e-05 8.8e-05 -0.000725 -0.425929 0.686694 -1.37906</acceleration>
          <wrench>-1.2e-05 1.3e-05 -0.00011 0 -0 0</wrench>
        </link>
        <link name='r_wrist_flection_link'>
          <pose frame=''>0.000574 0.303051 0.461844 -1.47775 1.24476 1.69765</pose>
          <velocity>-1.3e-05 -7e-06 1.2e-05 -1.5e-05 -0.000143 0.000277</velocity>
          <acceleration>0.000305 0.000154 -0.000803 1.34242 0.094059 -0.937771</acceleration>
          <wrench>8e-05 4.1e-05 -0.000211 0 -0 0</wrench>
        </link>
        <link name='waist_link'>
          <pose frame=''>-0.000139 -1e-06 0.580651 1.5708 0.000106 -0.000105</pose>
          <velocity>-5e-06 0 1.5e-05 0 0 -3e-06</velocity>
          <acceleration>-0.000193 0.000862 -1.4e-05 -1.07303 -0.027764 2.32408</acceleration>
          <wrench>-0.000296 0.001318 -2.1e-05 0 -0 0</wrench>
        </link>
      </model>
      <light name='my_light_01'>
        <pose frame=''>0 0 30 0 -0 0</pose>
      </light>
      <light name='my_light_02'>
        <pose frame=''>0 0 30 0 -0 0</pose>
      </light>
      <light name='my_light_03'>
        <pose frame=''>0 0 30 0 -0 0</pose>
      </light>
      <light name='my_light_04'>
        <pose frame=''>0 0 30 0 -0 0</pose>
      </light>
      <light name='my_light_05'>
        <pose frame=''>0 0 30 0 -0 0</pose>
      </light>
      <light name='my_light_06'>
        <pose frame=''>0 0 30 0 -0 0</pose>
      </light>
    </state>
    <gui fullscreen='0'>
      <camera name='user_camera'>
        <pose frame=''>-1.4629 0.76168 9.47755 3.14159 1.57079 3.14159</pose>
        <view_controller>orbit</view_controller>
        <projection_type>perspective</projection_type>
      </camera>
    </gui>
  </world>
</sdf>
